Doesn't work:

```
python3 run.py --debug --code 608060405260043610610057576000357c0100000000000000000000000000000000000000000000000000000000900463ffffffff1680635457114d1461005c5780638c423561146100a75780639453a854146100f2575b600080fd5b34801561006857600080fd5b50610091600480360381019080803590602001909291908035906020019092919050505061013d565b6040518082815260200191505060405180910390f35b3480156100b357600080fd5b506100dc600480360381019080803590602001909291908035906020019092919050505061015c565b6040518082815260200191505060405180910390f35b3480156100fe57600080fd5b506101276004803603810190808035906020019092919080359060200190929190505050610176565b6040518082815260200191505060405180910390f35b60008183101515610152578183039050610156565b8290505b92915050565b60008183101561016b57600080fd5b818303905092915050565b600082821115151561018457fe5b8183039050929150505600a165627a7a72305820042974cdb8bfeef6d37f8ff4aaa193b8e3fdb0917801f5ba51143e1e951e61410029 --input 9453a85400000000000000000000000000000000000000000000000000000000000000020000000000000000000000000000000000000000000000000000000000000001

/bin/sh: ./../build/bin/evm: Permission denied
Traceback (most recent call last):
  File "/Users/bdelb/tmp/secu/EasyFlow/taint_scripts/run.py", line 37, in run_evm
    last_op = json.loads(output_str.splitlines()[-3])["opName"]
IndexError: list index out of range

During handling of the above exception, another exception occurred:

Traceback (most recent call last):
  File "/Users/bdelb/tmp/secu/EasyFlow/taint_scripts/run.py", line 137, in <module>
    main(args.code, args.input, args.debug)
  File "/Users/bdelb/tmp/secu/EasyFlow/taint_scripts/run.py", line 59, in main
    last_op, taint_res = run_evm(code_str, input_str)
  File "/Users/bdelb/tmp/secu/EasyFlow/taint_scripts/run.py", line 39, in run_evm
    last_op = json.loads(output_str.splitlines()[-6])["opName"]
IndexError: list index out of range
```

